Workbook

Sheet Dashboard
A1: Monitoring Proyek Bot Trading
A2: Semua angka terhitung otomatis dari sheet lain. Tidak perlu diisi manual.
A3: Indikator | B3: Nilai | C3: Dari total | D3: Keterangan
A4: PROGRES PENGERJAAN
A5: Tugas Sprint 1 selesai | B5: ='Sprint 1 Harian'!E46 -> 0 | C5: ='Sprint 1 Harian'!E47 -> 40 | D5: Rincian di sheet Sprint 1 Harian
A6: Persentase tugas Sprint 1 | B6: =IFERROR(B5/C5,0) -> 0 | D6: Target 100% di akhir Hari 7
A7: File kode selesai | B7: ='Checklist Kode'!C44 -> 4 | C7: ='Checklist Kode'!C45 -> 39 | D7: 39 file total, 29 di antaranya Sprint 1
A8: Persentase file kode | B8: =IFERROR(B7/C7,0) -> 0.1025641
A9: Estimasi jam Sprint 1 | B9: ='Sprint 1 Harian'!E45 -> 61.7 | D9: Total estimasi seluruh tugas minggu 1
A10: STATUS GATE
A11: Gate lulus | B11: ='Gate Outcome'!D21 -> 0 | C11: =16 -> 16 | D11: Gate gagal berarti mengulang, bukan melanjutkan
A12: Gate gagal | B12: ='Gate Outcome'!D22 -> 0 | D12: Perlu tindakan sebelum lanjut
A13: Gate belum dicek | B13: ='Gate Outcome'!D23 -> 16
A14: HASIL LIVE
A15: Total transaksi | B15: ='Log Harian'!B72 -> 34 | D15: Di bawah 200 belum bisa dinilai secara statistik
A16: Win rate | B16: ='Log Harian'!B73 -> 0.52941176 | D16: 52-55% sudah termasuk bagus
A17: P&L kumulatif (Rp) | B17: ='Log Harian'!B74 -> -12500 | D17: BUKAN indikator keberhasilan di bulan pertama
A18: Rata-rata slippage aktual (bps) | B18: ='Log Harian'!B75 -> 3.4 | D18: Dibandingkan asumsi model di cost_model.py
A19: RISIKO
A20: Risiko skor 12 ke atas | B20: =COUNTIF(Risiko!E4:E14,">=12") -> 7 | C20: =11 -> 11 | D20: Wajib punya mitigasi aktif
A21: Risiko berstatus Terbuka | B21: =COUNTIF(Risiko!G4:G14,"Terbuka") -> 1 | D21: Belum ada mitigasi yang berjalan
A23: CARA PAKAI
A24: Sel berlatar kuning adalah sel yang diisi manual. Sisanya terhitung otomatis.
A25: Urutan pemakaian: BRD dibaca dan disetujui, lalu Framework untuk melihat arah 12 minggu,
A26: lalu Sprint 1 Harian sebagai checklist harian, Checklist Kode untuk melacak file,
A27: Gate Outcome untuk menilai apakah boleh lanjut, dan Log Harian setelah bot live.
A28: Keputusan dan Risiko diisi sepanjang proyek berjalan.
A30: Gate gagal berarti mengulang tahap itu. Menurunkan target agar terlihat lulus
A31: menghapus seluruh gunanya dokumen ini.

Sheet BRD
A1: Business Requirement Document
A2: Bot trading otomatis skala menit - disetujui sebelum Sprint 1 dimulai
A3: Bagian | B3: Isi | C3: Catatan / Verifikasi
A4: 1. LATAR BELAKANG
A5: Masalah | B5: Trading manual skala menit tidak bisa dilakukan konsisten oleh manusia: keputusan harus diambil tiap 60 detik, dan disiplin menurun saat rugi beruntun.
A6: Peluang | B6: Program bisa mengeksekusi aturan yang sama tanpa lelah dan tanpa emosi, serta mencatat setiap keputusan untuk dievaluasi.
A7: Kondisi pemilik proyek | B7: Junior developer, menguasai Python, memahami dasar orderbook, belum menguasai finance. | C7: Panduan istilah tersedia di dokumen terpisah
A8: 2. TUJUAN
A9: Tujuan utama | B9: Mendapat jawaban terukur: apakah satu pola trading benar-benar menguntungkan setelah seluruh biaya, atau hasil bagusnya kebetulan. | C9: Bukan 'menghasilkan uang' - itu akibat, bukan tujuan
A10: Tujuan sekunder | B10: Membangun infrastruktur yang bisa dipakai ulang untuk menguji pola berikutnya dalam hitungan hari, bukan minggu.
A11: Bukan tujuan | B11: Keuntungan besar dalam 3 bulan. Mengalahkan pasar. Membangun sistem yang bisa dijual.
A12: 3. DEFINISI BERHASIL
A13: Hari 7 | B13: Angka expectancy setelah biaya nyata diketahui, beserta t-statistic-nya. Infrastruktur siap menguji pola berikutnya. | C13: Diukur di sheet Gate Outcome
A14: Bulan 3 | B14: Sistem berjalan tanpa diawasi terus-menerus. Sharpe bersih di atas 1,0 pada data live minimal 6 minggu. Ada kondisi tertulis kapan bot harus dimatikan.
A15: Berhasil yang sering disalahpahami | B15: Temuan 'tidak ada edge' dalam 2 minggu DIHITUNG BERHASIL. Menghemat 10 minggu kerja dan infrastruktur tetap terpakai.
A16: 4. RUANG LINGKUP
A17: Termasuk | B17: Satu instrumen. Satu pola rule-based. Backtest dengan model biaya penuh. Eksekusi otomatis. Lapisan risiko dan kill switch. Live dengan modal mikro. Penyaring ML di Sprint 5.
A18: Tidak termasuk | B18: Multi-instrumen sebelum Sprint 6. Deep learning. High frequency trading. Analisis sentimen berita. Manajemen dana orang lain. Antarmuka pengguna.
A19: Pasar | B19: Kontrak berjangka kripto (perpetual futures) di bursa luar negeri. | C19: Alasan di sheet Keputusan
A20: Timeframe | B20: Bar 1 menit.
A21: 5. ASUMSI
A22: A1 | B22: Ongkos bolak-balik di perp kripto sekitar 11 bps (taker) atau 4 bps (maker). | C22: WAJIB diverifikasi Hari 1 dengan tarif akun sendiri
A23: A2 | B23: Pergerakan harga tipikal per menit cukup besar dibanding ongkos (rasio di atas 2x). | C23: WAJIB diverifikasi Hari 1 - kalau gagal, proyek berhenti
A24: A3 | B24: Data historis 1 menit tersedia gratis lewat ccxt untuk minimal 18 bulan. | C24: Diverifikasi Hari 1
A25: A4 | B25: Slippage sekitar 2 bps per sisi. | C25: TEBAKAN. Diganti angka nyata di Hari 7
A26: 6. BATASAN
A27: Anggaran pengembangan | B27: Rp 1.000.000. Terpakai untuk VPS sekitar Rp 300.000 per 3 bulan; sisanya cadangan.
A28: Modal trading | B28: Rp 2.000.000 - 5.000.000. Terpisah dari anggaran pengembangan. Diperlakukan sebagai uang yang sudah hilang. | C28: Isi angka pastinya sebelum Hari 6
A29: Waktu | B29: 12 minggu. Sprint 1 dipadatkan jadi 7 hari sampai live.
A30: Sumber daya | B30: Satu orang, paruh waktu.
A31: Regulasi | B31: Perlakuan pajak derivatif kripto lintas negara belum jelas. | C31: Konsultasikan sebelum menaikkan modal
A32: 7. ATURAN YANG MENGIKAT
A33: N1 | B33: Tidak ada uang sungguhan sebelum pengaman Hari 4 terbukti bekerja.
A34: N2 | B34: Tidak ada machine learning sebelum pola rule-based lolos gate.
A35: N3 | B35: Maksimal tiga parameter per strategi.
A36: N4 | B36: Modal tidak dinaikkan berdasarkan hasil minggu pertama, positif maupun negatif.
A37: N5 | B37: Syarat lulus tidak diturunkan agar bisa lanjut.
A38: N6 | B38: Tidak ada intervensi manual saat bot berjalan.
A40: Disetujui tanggal:

Sheet Framework
A1: Framework 12 Minggu
A2: Sprint tidak boleh dimulai sebelum sprint sebelumnya lulus gate
A3: Sprint | B3: Minggu | C3: Tujuan | D3: Deliverable utama | E3: Gate (syarat lulus) | F3: Target selesai | G3: Status | H3: Catatan
A4: 1 | B4: Minggu 1 | C4: Satu pola diuji jujur, eksekusi dan pengaman jalan, uang sungguhan masuk dalam jumlah mikro. | D4: 29 file kode inti + bot live | E4: Expectancy positif setelah biaya di data out-of-sample, t-stat > 2, bot live tanpa insiden | G4: Belum
A5: 2 | B5: Minggu 2-3 | C5: Menutup jarak antara hasil simulasi dan hasil nyata. Memperbaiki eksekusi, bukan strategi. | D5: repricer.py, slippage_report.py | E5: Selisih P&L nyata vs simulasi di bawah 30%, gate Sprint 1 masih lolos dengan biaya terkoreksi | G5: Belum
A6: 3 | B6: Minggu 4-5 | C6: Bot sanggup berjalan semalaman tanpa diawasi. | D6: watchdog.py, anomaly.py, prosedur pemulihan | E6: 4 minggu berjalan tanpa perbaikan darurat, nol desync posisi | G6: Belum
A7: 4 | B7: Minggu 6-7 | C7: Mengevaluasi seluruh transaksi nyata. Menentukan apakah modal boleh naik. | D7: live_review.py, aturan penskalaan tertulis | E7: Expectancy nyata positif dengan selang kepercayaan tidak melewati nol | G7: Belum
A8: 5 | B8: Minggu 8-9 | C8: Machine learning sebagai penyaring sinyal yang sudah terbukti. | D8: features.py, purged_cv.py, train.py, filter.py | E8: Penyaring menaikkan expectancy out-of-sample secara material, atau dibuang | G8: Belum
A9: 6 | B9: Minggu 10-12 | C9: Pola kedua yang tidak berkorelasi, dashboard, prosedur berhenti. | D9: strategi kedua, dashboard.py, shutdown.md | E9: Sharpe bersih di atas 1,0 pada data live gabungan minimal 6 minggu | G9: Belum

Sheet Sprint 1 Harian
A1: Sprint 1 - Rincian Harian
A2: Centang tiap tugas. Gate di akhir tiap hari menentukan boleh lanjut atau mengulang.
A3: Hari | B3: Fokus | C3: Tugas | D3: File terkait | E3: Jam | F3: Status | G3: Bukti selesai | H3: Catatan
A4: 1 | B4: Ongkos dan data | C4: Siapkan virtual environment dan pasang dependensi | D4: requirements.txt | E4: 0.5 | F4: Belum | G4: Perintah pip selesai tanpa error
C5: Jalankan scaffold.py untuk membuat seluruh struktur folder | D5: scaffold.py | E5: 0.2 | F5: Belum | G5: 42 file stub terbentuk
C6: Tulis model biaya: fee maker/taker, spread, slippage, funding | D6: src/core/cost_model.py | E6: 2 | F6: Belum | G6: python -m src.core.cost_model menampilkan rincian
C7: Tarik spesifikasi instrumen dari bursa (tick size, notional minimum) | D7: src/core/instruments.py | E7: 1.5 | F7: Belum | G7: Spesifikasi tersimpan, tidak ditulis manual
C8: Unduh 18 bulan bar 1 menit untuk 2-3 kandidat instrumen | D8: src/data/fetch_history.py | E8: 1 | F8: Belum | G8: File Parquet ada, celah data di bawah 1%
C9: Hitung rasio pergerakan harga terhadap ongkos | D9: scripts/analyze_costs.py | E9: 1.5 | F9: Belum | G9: Tabel rasio tercetak
C10: GATE: pilih instrumen dan catat alasannya | D10: lessons.md | E10: 0.3 | F10: Belum | G10: Rasio di atas 2x, alasan tertulis
A11: 2 | B11: Strategi dan uji | C11: Tulis kontrak dasar strategi | D11: src/strategy/base.py | E11: 1 | F11: Belum | G11: Kelas abstrak, satu metode
C12: Tulis strategi VWAP reversion, maksimal 3 parameter | D12: src/strategy/vwap_reversion.py | E12: 3 | F12: Belum | G12: Masuk bar, keluar sinyal, tidak menyentuh order
C13: Bangun mesin simulasi bar per bar yang memanggil cost_model | D13: src/backtest/engine.py | E13: 3 | F13: Belum | G13: Simulasi jalan, biaya terhitung tiap transaksi
C14: Hitung metrik: expectancy, t-stat, drawdown, Sharpe | D14: src/backtest/metrics.py | E14: 2 | F14: Belum | G14: Metrik keluar untuk satu run
C15: Bagi data latih dan uji, jalankan uji sensitivitas parameter | D15: src/backtest/validate.py | E15: 2 | F15: Belum | G15: Parameter dikunci di data lama
C16: GATE: 200+ trade out-of-sample, t-stat > 2, drawdown < 15% | D16: scripts/run_backtest.py | E16: 1 | F16: Belum | G16: Laporan lulus/gagal per kriteria
A17: 3 | B17: Eksekusi testnet | C17: Bungkus API bursa di satu file | D17: src/execution/broker.py | E17: 2.5 | F17: Belum | G17: Hanya file ini yang menyentuh jaringan bursa
C18: Kirim limit order dengan client order ID idempoten | D18: src/execution/order_manager.py | E18: 4 | F18: Belum | G18: Order terkirim di testnet
C19: Tangani partial fill, penolakan, dan pembatalan setelah timeout | D19: src/execution/order_manager.py | E19: 2 | F19: Belum | G19: Ketiga kasus tertangani
C20: Sambungkan aliran bar langsung dengan reconnect otomatis | D20: src/data/stream.py | E20: 2 | F20: Belum | G20: Bar masuk tiap menit, reconnect jalan
C21: Catat slippage tiap fill | D21: src/execution/slippage_tracker.py | E21: 1.5 | F21: Belum | G21: Selisih harga sinyal vs fill tercatat
C22: GATE: putus jaringan sengaja, pastikan tidak ada order ganda | D22: tests/test_order_manager.py | E22: 1 | F22: Belum | G22: Uji lolos, log bersih
A23: 4 | B23: Risiko dan pengaman | C23: Batas rugi harian dan batas posisi tertanam di kode | D23: src/risk/limits.py | E23: 2.5 | F23: Belum | G23: Sinyal ditolak saat batas tersentuh
C24: Ukuran posisi berbasis volatilitas, dibulatkan ke kelipatan bursa | D24: src/risk/sizing.py | E24: 2 | F24: Belum | G24: Ukuran valid, di atas notional minimum
C25: Pencocokan posisi bot vs bursa tiap 30 detik | D25: src/execution/reconciler.py | E25: 2 | F25: Belum | G25: Selisih terdeteksi dan memicu berhenti
C26: Notifikasi Telegram untuk fill, error, batas tersentuh | D26: src/ops/notifier.py | E26: 1.5 | F26: Belum | G26: Pesan masuk ke ponsel
C27: Kill switch yang bisa ditekan dari Telegram | D27: src/ops/killswitch.py | E27: 2 | F27: Belum | G27: Posisi benar-benar tertutup saat ditekan
C28: GATE: matikan paksa saat posisi terbuka, pastikan pulih benar | D28: tests/test_limits.py | E28: 1 | F28: Belum | G28: State benar setelah restart
A29: 5 | B29: Pengemasan | C29: Log JSON terstruktur | D29: src/ops/logger.py | E29: 1.5 | F29: Belum | G29: Log bisa dikueri, bukan sekadar dibaca
C30: Jahit semua lapisan jadi satu runner testnet | D30: src/runner/paper.py | E30: 3 | F30: Belum | G30: Sistem lengkap jalan di testnet
C31: Bungkus jadi image Docker dan jalankan di VPS | D31: Dockerfile | E31: 2 | F31: Belum | G31: Container jalan di VPS
C32: Batasi jam buka posisi ke jendela yang diawasi | D32: config/config.yaml | E32: 0.5 | F32: Belum | G32: Di luar jam, posisi ditutup
C33: GATE: jalan satu jendela penuh tanpa disentuh, nol desync | D33: - | E33: 4 | F33: Belum | G33: Log bersih sepanjang jendela
A34: 6 | B34: Live modal mikro | C34: Buat sub-akun terpisah, isi modal yang siap hilang | D34: - | E34: 0.5 | F34: Belum | G34: Saldo sesuai rencana
C35: API key: izin trading saja, tanpa penarikan, dengan IP whitelist | D35: config/secrets.env | E35: 0.5 | F35: Belum | G35: Izin terverifikasi di panel bursa
C36: Set leverage 1x dan isolated margin | D36: config/config.yaml | E36: 0.2 | F36: Belum | G36: Terkonfirmasi di bursa
C37: Jalankan runner live, risiko 0,1% per transaksi | D37: src/runner/live.py | E37: 1 | F37: Belum | G37: Transaksi pertama tercatat
C38: Laporan harian otomatis ke Telegram | D38: scripts/daily_report.py | E38: 1.5 | F38: Belum | G38: Laporan terkirim
C39: ATURAN: tanpa intervensi manual, tanpa ubah parameter | D39: - | E39: 0 | F39: Belum | G39: Tidak ada perubahan di git log hari ini
A40: 7 | B40: Koreksi dan putusan | C40: Hitung slippage rata-rata dan sebarannya dari log fill | D40: src/execution/slippage_tracker.py | E40: 1.5 | F40: Belum | G40: Angka bps keluar
...

Sheet Checklist Kode
A1: Checklist File Kode
A2: 42 file. Kolom Status dan Test diisi manual seiring pengerjaan.
A3: File | B3: Lapisan | C3: Sprint | D3: Fungsi | E3: Status | F3: Ada test | G3: Catatan
A4: src/core/cost_model.py | B4: core | C4: 1 | D4: Satu-satunya sumber kebenaran ongkos. Dipanggil backtest DAN live. | E4: Selesai | F4: Belum
A5: src/core/instruments.py | B5: core | C5: 1 | D5: Spesifikasi instrumen dari bursa: tick size, step size, notional minimum. | E5: Belum | F5: Belum
A6: src/core/types.py | B6: core | C6: 1 | D6: Bentuk data bersama: Bar, Signal, Order, Fill, Position. | E6: Belum | F6: Belum
A7: src/data/fetch_history.py | B7: data | C7: 1 | D7: Unduh bar 1 menit dari bursa ke Parquet. | E7: Selesai | F7: Belum
A8: src/data/store.py | B8: data | C8: 1 | D8: Baca data historis, bagi data latih dan data uji. | E8: Selesai | F8: Belum
A9: src/data/stream.py | B9: data | C9: 1 | D9: Aliran bar langsung lewat WebSocket. Keluaran identik dengan store.py. | E9: Belum | F9: Belum
A10: src/strategy/base.py | B10: strategy | C10: 1 | D10: Kontrak yang wajib dipenuhi tiap strategi. | E10: Belum | F10: Belum
A11: src/strategy/vwap_reversion.py | B11: strategy | C11: 1 | D11: Strategi pertama. Maksimal tiga parameter. | E11: Belum | F11: Belum
A12: src/backtest/engine.py | B12: backtest | C12: 1 | D12: Simulasi bar per bar, memanggil cost_model. | E12: Belum | F12: Belum
A13: src/backtest/metrics.py | B13: backtest | C13: 1 | D13: Expectancy, t-stat, drawdown, Sharpe, win rate. | E13: Belum | F13: Belum
A14: src/backtest/validate.py | B14: backtest | C14: 1 | D14: Pembagian out-of-sample dan uji sensitivitas parameter. | E14: Belum | F14: Belum
A15: src/execution/broker.py | B15: execution | C15: 1 | D15: SATU-SATUNYA file yang menyentuh API bursa. | E15: Belum | F15: Belum
... A42: src/analysis/dashboard.py | B42: analysis | C42: 6 | D42: Dashboard HTML: equity curve, slippage, drawdown. | E42: Belum | F42: Belum
A44: File selesai | C44: =COUNTIF(E4:E42,"Selesai") -> 4
A45: Total file | C45: =COUNTA(A4:A42) -> 39
A46: Progres | C46: =IFERROR(C44/C45,0) -> 0.1025641

Sheet Gate Outcome
A1: Gate dan Outcome
A2: Isi kolom Aktual. Kolom Lulus terhitung otomatis. Gate gagal berarti mengulang, bukan melanjutkan.
A3: ID | B3: Sprint | C3: Kriteria | D3: Target | E3: Arah | F3: Aktual | G3: Lulus | H3: Tgl dicek | I3: Catatan
A4: G1 | B4: 1 | C4: Rasio pergerakan harga terhadap ongkos (persentil 75) | D4: 2 | E4: >= | G4: =IF(F4="","-",IF(E4=">=",IF(F4>=D4,"LULUS","GAGAL"),IF(E4=">",IF(F4>D4,"LULUS","GAGAL"),IF(E4="<=",IF(F4<=D4,"LULUS","GAGAL"),"?")))) -> - | H4: Hari 1
A5: G2 | B5: 1 | C5: Jumlah transaksi di data out-of-sample | D5: 200 | E5: >= | G5: =IF(F5="","-",IF(E5=">=",IF(F5>=D5,"LULUS","GAGAL"),IF(E5=">",IF(F5>D5,"LULUS","GAGAL"),IF(E5="<=",IF(F5<=D5,"LULUS","GAGAL"),"?")))) -> - | H5: Hari 2
A6: G3 | B6: 1 | C6: Expectancy per transaksi setelah biaya (bps) | D6: 0 | E6: > | G6: =IF(F6="","-",IF(E6=">=",IF(F6>=D6,"LULUS","GAGAL"),IF(E6=">",IF(F6>D6,"LULUS","GAGAL"),IF(E6="<=",IF(F6<=D6,"LULUS","GAGAL"),"?")))) -> - | H6: Hari 2
A7: G4 | B7: 1 | C7: t-statistic expectancy | D7: 2 | E7: >= | G7: =IF(F7="","-",IF(E7=">=",IF(F7>=D7,"LULUS","GAGAL"),IF(E7=">",IF(F7>D7,"LULUS","GAGAL"),IF(E7="<=",IF(F7<=D7,"LULUS","GAGAL"),"?")))) -> - | H7: Hari 2
A8: G5 | B8: 1 | C8: Maximum drawdown (%) | D8: 15 | E8: <= | G8: =IF(F8="","-",IF(E8=">=",IF(F8>=D8,"LULUS","GAGAL"),IF(E8=">",IF(F8>D8,"LULUS","GAGAL"),IF(E8="<=",IF(F8<=D8,"LULUS","GAGAL"),"?")))) -> - | H8: Hari 2
A9: G6 | B9: 1 | C9: Penurunan hasil saat parameter digeser 20% (%) | D9: 30 | E9: <= | G9: =IF(F9="","-",IF(E9=">=",IF(F9>=D9,"LULUS","GAGAL"),IF(E9=">",IF(F9>D9,"LULUS","GAGAL"),IF(E9="<=",IF(F9<=D9,"LULUS","GAGAL"),"?")))) -> - | H9: Hari 2
A10: G7 | B10: 1 | C10: Order ganda setelah putus koneksi (jumlah) | D10: 0 | E10: <= | G10: =IF(F10="","-",IF(E10=">=",IF(F10>=D10,"LULUS","GAGAL"),IF(E10=">",IF(F10>D10,"LULUS","GAGAL"),IF(E10="<=",IF(F10<=D10,"LULUS","GAGAL"),"?")))) -> - | H10: Hari 3
A11: G8 | B11: 1 | C11: Desync posisi bot vs bursa selama uji (jumlah) | D11: 0 | E11: <= | G11: =IF(F11="","-",IF(E11=">=",IF(F11>=D11,"LULUS","GAGAL"),IF(E11=">",IF(F11>D11,"LULUS","GAGAL"),IF(E11="<=",IF(F11<=D11,"LULUS","GAGAL"),"?")))) -> - | H11: Hari 5
A12: G9 | B12: 1 | C12: Insiden operasional saat live (jumlah) | D12: 0 | E12: <= | G12: =IF(F12="","-",IF(E12=">=",IF(F12>=D12,"LULUS","GAGAL"),IF(E12=">",IF(F12>D12,"LULUS","GAGAL"),IF(E12="<=",IF(F12<=D12,"LULUS","GAGAL"),"?")))) -> - | H12: Hari 6
A13: G10 | B13: 1 | C13: Slippage nyata dibanding asumsi model (rasio) | D13: 1.5 | E13: <= | G13: =IF(F13="","-",IF(E13=">=",IF(F13>=D13,"LULUS","GAGAL"),IF(E13=">",IF(F13>D13,"LULUS","GAGAL"),IF(E13="<=",IF(F13<=D13,"LULUS","GAGAL"),"?")))) -> - | H13: Hari 7
A14: G11 | B14: 1 | C14: Expectancy setelah slippage nyata dimasukkan (bps) | D14: 0 | E14: > | G14: =IF(F14="","-",IF(E14=">=",IF(F14>=D14,"LULUS","GAGAL"),IF(E14=">",IF(F14>D14,"LULUS","GAGAL"),IF(E14="<=",IF(F14<=D14,"LULUS","GAGAL"),"?")))) -> - | H14: Hari 7
A15: G12 | B15: 2 | C15: Selisih P&L nyata terhadap simulasi (%) | D15: 30 | E15: <= | G15: =IF(F15="","-",IF(E15=">=",IF(F15>=D15,"LULUS","GAGAL"),IF(E15=">",IF(F15>D15,"LULUS","GAGAL"),IF(E15="<=",IF(F15<=D15,"LULUS","GAGAL"),"?")))) -> - | H15: Minggu 3
... A19: G16 | B19: 6 | C19: Sharpe bersih pada data live minimal 6 minggu | D19: 1 | E19: >= | G19: =IF(F19="","-",IF(E19=">=",IF(F19>=D19,"LULUS","GAGAL"),IF(E19=">",IF(F19>D19,"LULUS","GAGAL"),IF(E19="<=",IF(F19<=D19,"LULUS","GAGAL"),"?")))) -> - | H19: Minggu 12
C21: Gate lulus | D21: =COUNTIF(G4:G19,"LULUS") -> 0
C22: Gate gagal | D22: =COUNTIF(G4:G19,"GAGAL") -> 0
C23: Belum dicek | D23: =COUNTIF(G4:G19,"-") -> 16
C25: Arah: >= artinya aktual harus lebih besar atau sama dengan target. <= artinya harus lebih kecil atau sama.

Sheet Log Harian
A1: Log Harian Live
A2: Diisi tiap hari sejak Hari 6. Satu baris per hari. Contoh di baris 4 - hapus setelah paham formatnya.
A3: Tanggal | B3: Trade | C3: Menang | D3: Kalah | E3: Slip model bps | F3: Slip aktual bps | G3: Selisih | H3: P&L bersih | I3: Insiden | J3: Catatan
A4: 2026-09-15 | B4: 34 | C4: 18 | D4: 16 | E4: 2 | F4: 3.4 | G4: =IFERROR(F4/E4,"") -> 1.7 | H4: -12500 | I4: Tidak ada | J4: CONTOH - hapus baris ini
G5: =IFERROR(F5/E5,"")
G6: =IFERROR(F6/E6,"")
G7: =IFERROR(F7/E7,"")
G8: =IFERROR(F8/E8,"")
G9: =IFERROR(F9/E9,"")
G10: =IFERROR(F10/E10,"")
G11: =IFERROR(F11/E11,"")
G12: =IFERROR(F12/E12,"")
G13: =IFERROR(F13/E13,"")
G14: =IFERROR(F14/E14,"")
G15: =IFERROR(F15/E15,"")
G16: =IFERROR(F16/E16,"")
... G69: =IFERROR(F69/E69,"")
A72: Total trade | B72: =SUM(B4:B70) -> 34
A73: Win rate | B73: =IFERROR(SUM(C4:C70)/SUM(B4:B70),0) -> 0.52941176
A74: P&L kumulatif | B74: =SUM(H4:H70) -> -12500
A75: Rata-rata slippage aktual | B75: =IFERROR(AVERAGE(F4:F70),0) -> 3.4
A77: Kolom Selisih = slippage aktual dibagi slippage model. Di atas 1,5x berarti gate G10 gagal dan model biaya harus dikoreksi.
A78: P&L bersih diisi dalam rupiah, setelah seluruh fee. Angka negatif ditulis dengan tanda minus.

Sheet Keputusan
A1: Catatan Keputusan
A2: Keputusan yang tidak dicatat akan diperdebatkan ulang dari nol dua minggu lagi.
A3: Tanggal | B3: Keputusan | C3: Alasan | D3: Alternatif yang ditolak | E3: Ditinjau ulang kapan
B4: Pasar: kontrak berjangka kripto, bukan saham | C4: Satu-satunya pasar dengan ongkos cukup rendah untuk skala menit, akses API terbuka, tanpa syarat modal besar. | D4: Saham IDX (ongkos 12-15x pergerakan tipikal, tidak ada API retail). Saham AS (terhalang aturan Pattern Day Trader di bawah USD 25.000). | E4: Sprint 4
B5: TradingView tidak dipakai | C5: Backtester-nya mengasumsikan order terisi di harga bar tanpa model spread dan antrian, dan alert-nya tidak menerima umpan balik fill. | D5: Hybrid webhook TradingView ke eksekutor sendiri. | E5: Tidak ditinjau ulang
B6: Satu instrumen likuiditas tinggi di awal | C6: Aset dengan perdagangan tipis menghasilkan backtest yang menipu karena harga di layar bukan harga yang bisa didapat. | D6: Altcoin dengan volatilitas lebih tinggi. | E6: Sprint 6
B7: Aturan sederhana dulu, ML di Sprint 5 | C7: Kalau aturan dasarnya tidak punya keunggulan, ML hanya menemukan pola di keacakan dengan lebih meyakinkan. | D7: Langsung pakai LightGBM atau LSTM sebagai penghasil sinyal. | E7: Sprint 5
B8: Leverage 1x, isolated margin | C8: Leverage memperbesar apa pun yang sudah ada, termasuk kesalahan. | D8: Leverage 3-5x untuk memperbesar keuntungan absolut. | E8: Sprint 4
B9: Uang sungguhan masuk di Hari 6, jumlah mikro | C9: Slippage tidak bisa diukur di testnet, dan seluruh penilaian strategi bergantung pada model biaya. | D9: Paper trading penuh selama sebulan sebelum live. | E9: Tidak ditinjau ulang
B10: Instrumen terpilih: ______ | C10: Diisi setelah Hari 1 | E10: Sprint 2

Sheet Risiko
A1: Daftar Risiko
A2: Skor = dampak x kemungkinan, skala 1-5 masing-masing. Skor 12 ke atas wajib ada mitigasi aktif.
A3: ID | B3: Risiko | C3: Dampak | D3: Kemungkinan | E3: Skor | F3: Mitigasi | G3: Status
A4: R1 | B4: Overfitting: hasil bagus hanya muncul di rentang parameter sempit | C4: 5 | D4: 4 | E4: =C4*D4 -> 20 | F4: Maksimal 3 parameter. Uji sensitivitas plus minus 20%. Evaluasi hanya di data out-of-sample. | G4: Aktif
A5: R2 | B5: Backtest tanpa ongkos penuh menghasilkan kurva keuntungan palsu | C5: 5 | D5: 3 | E5: =C5*D5 -> 15 | F5: cost_model.py wajib dipanggil di tiap transaksi simulasi. Slippage dikoreksi dengan angka nyata di Hari 7. | G5: Aktif
A6: R3 | B6: Order ganda setelah putus koneksi | C6: 5 | D6: 4 | E6: =C6*D6 -> 20 | F6: Client order ID idempoten. Diuji dengan memutus jaringan sengaja sebelum uang masuk. | G6: Aktif
A7: R4 | B7: Posisi bot berbeda dari posisi bursa tanpa ketahuan | C7: 5 | D7: 3 | E7: =C7*D7 -> 15 | F7: Rekonsiliasi tiap 30 detik. Selisih memicu berhenti, bukan diperbaiki diam-diam. | G7: Aktif
A8: R5 | B8: Modal dinaikkan setelah beruntun menang di sampel kecil | C8: 4 | D8: 4 | E8: =C8*D8 -> 16 | F8: Aturan tertulis: modal tidak naik sebelum Sprint 4 dan selang kepercayaan expectancy tidak melewati nol. | G8: Aktif
A9: R6 | B9: Intervensi manual merusak validitas data | C9: 4 | D9: 3 | E9: =C9*D9 -> 12 | F9: Tidak ada pembatalan trade manual. Perubahan apa pun dilakukan dengan bot dimatikan dan dicatat di lessons.md. | G9: Aktif
A10: R7 | B10: API key bocor atau disalahgunakan | C10: 5 | D10: 2 | E10: =C10*D10 -> 10 | F10: Izin trading saja tanpa penarikan. IP whitelist ke VPS. secrets.env tidak masuk git. | G10: Aktif
A11: R8 | B11: Tidak ada edge sama sekali di pola pertama | C11: 3 | D11: 4 | E11: =C11*D11 -> 12 | F11: Diperlakukan sebagai hasil sah, bukan kegagalan. Infrastruktur dipakai ulang untuk pola berikutnya. | G11: Diterima
A12: R9 | B12: Ketidakjelasan pajak derivatif kripto lintas negara | C12: 3 | D12: 3 | E12: =C12*D12 -> 9 | F12: Konsultasi sebelum modal dinaikkan. Modal tetap mikro sampai jelas. | G12: Terbuka
A13: R10 | B13: Bursa membatasi akses atau mengubah aturan | C13: 4 | D13: 2 | E13: =C13*D13 -> 8 | F13: Semua akses bursa terpusat di broker.py, sehingga pindah bursa hanya mengubah satu file. | G13: Aktif
A14: R11 | B14: Kehabisan waktu karena target 7 hari terlalu padat | C14: 3 | D14: 3 | E14: =C14*D14 -> 9 | F14: Gate harian. Gate gagal berarti mengulang hari itu, bukan memaksa lanjut ke hari berikutnya. | G14: Aktif
